2024-06-26 20:50:49,672 - ERROR - Error occurred: module 'user_profile' has no attribute 'biography'
Traceback (most recent call last):
  File "/Users/rwatkins_1/Python projects/preprints_recommender/src/update_user_recs_urssi.py", line 624, in <module>
    update_recommendations()
  File "/Users/rwatkins_1/Python projects/preprints_recommender/src/update_user_recs_urssi.py", line 585, in update_recommendations
    user_profile.biography, arxiv_articles, "arxiv_"
    ^^^^^^^^^^^^^^^^^^^^^^
AttributeError: module 'user_profile' has no attribute 'biography'
2024-06-26 20:52:11,372 - ERROR - Error occurred: module 'user_profile' has no attribute 'biography'
Traceback (most recent call last):
  File "/Users/rwatkins_1/Python projects/preprints_recommender/src/update_user_recs_urssi.py", line 624, in <module>
    update_recommendations()
  File "/Users/rwatkins_1/Python projects/preprints_recommender/src/update_user_recs_urssi.py", line 585, in update_recommendations
    user_profile.biography, arxiv_articles, "arxiv_"
    ^^^^^^^^^^^^^^^^^^^^^^
AttributeError: module 'user_profile' has no attribute 'biography'
2024-06-26 20:53:08,290 - ERROR - Error occurred: module 'user_profile' has no attribute 'biography'
Traceback (most recent call last):
  File "/Users/rwatkins_1/Python projects/preprints_recommender/src/update_user_recs_urssi.py", line 624, in <module>
    update_recommendations()
  File "/Users/rwatkins_1/Python projects/preprints_recommender/src/update_user_recs_urssi.py", line 585, in update_recommendations
    user_profile.biography, arxiv_articles, "arxiv_"
    ^^^^^^^^^^^^^^^^^^^^^^
AttributeError: module 'user_profile' has no attribute 'biography'
2024-06-26 20:53:54,746 - ERROR - Error occurred: module 'user_profile' has no attribute 'biography'
Traceback (most recent call last):
  File "/Users/rwatkins_1/Python projects/preprints_recommender/src/update_user_recs_urssi.py", line 626, in <module>
    update_recommendations()
  File "/Users/rwatkins_1/Python projects/preprints_recommender/src/update_user_recs_urssi.py", line 587, in update_recommendations
    user_profile.biography, arxiv_articles, "arxiv_"
    ^^^^^^^^^^^^^^^^^^^^^^
AttributeError: module 'user_profile' has no attribute 'biography'
2024-06-26 20:56:03,142 - ERROR - Error occurred: module 'user_profile' has no attribute 'biography'
Traceback (most recent call last):
  File "/Users/rwatkins_1/Python projects/preprints_recommender/src/update_user_recs_urssi.py", line 627, in <module>
    update_recommendations()
  File "/Users/rwatkins_1/Python projects/preprints_recommender/src/update_user_recs_urssi.py", line 588, in update_recommendations
    user_profile.biography, arxiv_articles, "arxiv_"
    ^^^^^^^^^^^^^^^^^^^^^^
AttributeError: module 'user_profile' has no attribute 'biography'
2024-06-26 21:00:43,576 - ERROR - Error occurred: module 'user_profile' has no attribute 'biography'
Traceback (most recent call last):
  File "/Users/rwatkins_1/Python projects/preprints_recommender/src/update_user_recs_urssi.py", line 627, in <module>
    research_interests()
  File "/Users/rwatkins_1/Python projects/preprints_recommender/src/update_user_recs_urssi.py", line 570, in research_interests
    keywords = get_keywords_llm(user_profile.biography)
                                ^^^^^^^^^^^^^^^^^^^^^^
AttributeError: module 'user_profile' has no attribute 'biography'
2024-06-26 21:02:52,538 - ERROR - Error occurred: module 'user_profile' has no attribute 'biography'
Traceback (most recent call last):
  File "/Users/rwatkins_1/Python projects/preprints_recommender/src/update_user_recs_urssi.py", line 627, in <module>
    research_interests()
  File "/Users/rwatkins_1/Python projects/preprints_recommender/src/update_user_recs_urssi.py", line 570, in research_interests
    keywords = get_keywords_llm(user_profile.biography)
                                ^^^^^^^^^^^^^^^^^^^^^^
AttributeError: module 'user_profile' has no attribute 'biography'
2024-06-26 21:09:08,471 - ERROR - Error occurred: module 'user_profile' has no attribute 'biography'
Traceback (most recent call last):
  File "/Users/rwatkins_1/Python projects/preprints_recommender/src/update_user_recs_urssi.py", line 627, in <module>
    research_interests()
  File "/Users/rwatkins_1/Python projects/preprints_recommender/src/update_user_recs_urssi.py", line 570, in research_interests
    research_interests = get_keywords_llm(user_profile.biography)
                                          ^^^^^^^^^^^^^^^^^^^^^^
AttributeError: module 'user_profile' has no attribute 'biography'
2024-06-26 21:09:27,365 - ERROR - Error occurred: module 'user_profile' has no attribute 'biography'
Traceback (most recent call last):
  File "/Users/rwatkins_1/Python projects/preprints_recommender/src/update_user_recs_urssi.py", line 627, in <module>
    research_interests()
  File "/Users/rwatkins_1/Python projects/preprints_recommender/src/update_user_recs_urssi.py", line 570, in research_interests
    research_interests = get_keywords_llm(user_profile.biography)
                                          ^^^^^^^^^^^^^^^^^^^^^^
AttributeError: module 'user_profile' has no attribute 'biography'
2024-06-26 21:09:46,651 - ERROR - Error occurred: module 'user_profile' has no attribute 'biography'
Traceback (most recent call last):
  File "/Users/rwatkins_1/Python projects/preprints_recommender/src/update_user_recs_urssi.py", line 628, in <module>
    research_interests()
  File "/Users/rwatkins_1/Python projects/preprints_recommender/src/update_user_recs_urssi.py", line 570, in research_interests
    research_interests = get_keywords_llm(user_profile.biography)
                                          ^^^^^^^^^^^^^^^^^^^^^^
AttributeError: module 'user_profile' has no attribute 'biography'
2024-06-26 21:13:52,480 - ERROR - Error occurred: module 'user_profile' has no attribute 'biography'
Traceback (most recent call last):
  File "/Users/rwatkins_1/Python projects/preprints_recommender/src/update_user_recs_urssi.py", line 627, in <module>
    research_interests()
  File "/Users/rwatkins_1/Python projects/preprints_recommender/src/update_user_recs_urssi.py", line 570, in research_interests
    keywords = get_keywords_llm(user_profile.biography)
                                ^^^^^^^^^^^^^^^^^^^^^^
AttributeError: module 'user_profile' has no attribute 'biography'
2024-06-26 21:16:29,750 - ERROR - Error occurred: module 'user_profile' has no attribute 'biography'
Traceback (most recent call last):
  File "/Users/rwatkins_1/Python projects/preprints_recommender/src/update_user_recs_urssi.py", line 627, in <module>
    research_interests()
  File "/Users/rwatkins_1/Python projects/preprints_recommender/src/update_user_recs_urssi.py", line 570, in research_interests
    research_interests_keywords = get_keywords_llm(user_profile.biography)
                                                   ^^^^^^^^^^^^^^^^^^^^^^
AttributeError: module 'user_profile' has no attribute 'biography'
2024-06-26 21:16:57,935 - ERROR - Error occurred: module 'user_profile' has no attribute 'biography'
Traceback (most recent call last):
  File "/Users/rwatkins_1/Python projects/preprints_recommender/src/update_user_recs_urssi.py", line 628, in <module>
    research_interests()
  File "/Users/rwatkins_1/Python projects/preprints_recommender/src/update_user_recs_urssi.py", line 571, in research_interests
    research_interests_keywords = get_keywords_llm(user_profile.biography)
                                                   ^^^^^^^^^^^^^^^^^^^^^^
AttributeError: module 'user_profile' has no attribute 'biography'
2024-06-26 21:17:48,249 - ERROR - Error occurred: module 'user_profile' has no attribute 'biography'
Traceback (most recent call last):
  File "/Users/rwatkins_1/Python projects/preprints_recommender/src/update_user_recs_urssi.py", line 628, in <module>
    research_interests()
  File "/Users/rwatkins_1/Python projects/preprints_recommender/src/update_user_recs_urssi.py", line 571, in research_interests
    research_interests_keywords = get_keywords_llm(user_profile.biography)
                                                   ^^^^^^^^^^^^^^^^^^^^^^
AttributeError: module 'user_profile' has no attribute 'biography'
2024-06-26 21:19:34,557 - ERROR - Error occurred: module 'user_profile' has no attribute 'biography'
Traceback (most recent call last):
  File "/Users/rwatkins_1/Python projects/preprints_recommender/src/update_user_recs_urssi.py", line 631, in <module>
    research_interests()
  File "/Users/rwatkins_1/Python projects/preprints_recommender/src/update_user_recs_urssi.py", line 570, in research_interests
    research_interests_keywords = get_keywords_llm(user_profile.biography)
                                                   ^^^^^^^^^^^^^^^^^^^^^^
AttributeError: module 'user_profile' has no attribute 'biography'
2024-06-26 21:20:01,609 - ERROR - Error occurred: module 'user_profile' has no attribute 'biography'
Traceback (most recent call last):
  File "/Users/rwatkins_1/Python projects/preprints_recommender/src/update_user_recs_urssi.py", line 632, in <module>
    research_interests()
  File "/Users/rwatkins_1/Python projects/preprints_recommender/src/update_user_recs_urssi.py", line 571, in research_interests
    research_interests_keywords = get_keywords_llm(user_profile.biography)
                                                   ^^^^^^^^^^^^^^^^^^^^^^
AttributeError: module 'user_profile' has no attribute 'biography'
2024-06-26 21:22:45,289 - ERROR - Error occurred: module 'user_profile' has no attribute 'biography'
Traceback (most recent call last):
  File "/Users/rwatkins_1/Python projects/preprints_recommender/src/update_user_recs_urssi.py", line 632, in <module>
    update_recommendations()
  File "/Users/rwatkins_1/Python projects/preprints_recommender/src/update_user_recs_urssi.py", line 586, in update_recommendations
    research_interests()
  File "/Users/rwatkins_1/Python projects/preprints_recommender/src/update_user_recs_urssi.py", line 570, in research_interests
    research_interests_keywords = get_keywords_llm(user_profile.biography)
                                                   ^^^^^^^^^^^^^^^^^^^^^^
AttributeError: module 'user_profile' has no attribute 'biography'
2024-06-26 21:25:08,089 - ERROR - Error occurred: module 'user_profile' has no attribute 'biography'
Traceback (most recent call last):
  File "/Users/rwatkins_1/Python projects/preprints_recommender/src/update_user_recs_urssi.py", line 630, in <module>
    update_recommendations()
  File "/Users/rwatkins_1/Python projects/preprints_recommender/src/update_user_recs_urssi.py", line 584, in update_recommendations
    research_interests()
  File "/Users/rwatkins_1/Python projects/preprints_recommender/src/update_user_recs_urssi.py", line 570, in research_interests
    research_interests_keywords = get_keywords_llm(user_profile.biography)
                                                   ^^^^^^^^^^^^^^^^^^^^^^
AttributeError: module 'user_profile' has no attribute 'biography'
2024-06-26 21:26:10,426 - ERROR - Error occurred: module 'user_profile' has no attribute 'biography'
Traceback (most recent call last):
  File "/Users/rwatkins_1/Python projects/preprints_recommender/src/update_user_recs_urssi.py", line 630, in <module>
    update_recommendations()
  File "/Users/rwatkins_1/Python projects/preprints_recommender/src/update_user_recs_urssi.py", line 584, in update_recommendations
    research_interests()
  File "/Users/rwatkins_1/Python projects/preprints_recommender/src/update_user_recs_urssi.py", line 570, in research_interests
    research_interests_keywords = get_keywords_llm(user_profile.biography)
                                                   ^^^^^^^^^^^^^^^^^^^^^^
AttributeError: module 'user_profile' has no attribute 'biography'
2024-06-26 21:35:10,127 - ERROR - Error occurred: [Errno 2] No such file or directory: '/Users/rwatkins_1/Python projects/preprints_recommender/src/src/discipline_dissimilarity_matrix.csv'
Traceback (most recent call last):
  File "/Users/rwatkins_1/Python projects/preprints_recommender/src/update_user_recs_urssi.py", line 630, in <module>
    update_recommendations()
  File "/Users/rwatkins_1/Python projects/preprints_recommender/src/update_user_recs_urssi.py", line 585, in update_recommendations
    update_discipline()
  File "/Users/rwatkins_1/Python projects/preprints_recommender/src/update_user_recs_urssi.py", line 576, in update_discipline
    user_discipline = select_discipline(user_profile.biography)
                      ^^^^^^^^^^^^^^^^^^^^^^^^^^^^^^^^^^^^^^^^^
  File "/Users/rwatkins_1/Python projects/preprints_recommender/src/update_user_recs_urssi.py", line 149, in select_discipline
    dissim_df = pd.read_csv(
                ^^^^^^^^^^^^
  File "/Users/rwatkins_1/anaconda3/envs/preprint_recs_venv/lib/python3.11/site-packages/pandas/io/parsers/readers.py", line 1026, in read_csv
    return _read(filepath_or_buffer, kwds)
           ^^^^^^^^^^^^^^^^^^^^^^^^^^^^^^^
  File "/Users/rwatkins_1/anaconda3/envs/preprint_recs_venv/lib/python3.11/site-packages/pandas/io/parsers/readers.py", line 620, in _read
    parser = TextFileReader(filepath_or_buffer, **kwds)
             ^^^^^^^^^^^^^^^^^^^^^^^^^^^^^^^^^^^^^^^^^^
  File "/Users/rwatkins_1/anaconda3/envs/preprint_recs_venv/lib/python3.11/site-packages/pandas/io/parsers/readers.py", line 1620, in __init__
    self._engine = self._make_engine(f, self.engine)
                   ^^^^^^^^^^^^^^^^^^^^^^^^^^^^^^^^^
  File "/Users/rwatkins_1/anaconda3/envs/preprint_recs_venv/lib/python3.11/site-packages/pandas/io/parsers/readers.py", line 1880, in _make_engine
    self.handles = get_handle(
                   ^^^^^^^^^^^
  File "/Users/rwatkins_1/anaconda3/envs/preprint_recs_venv/lib/python3.11/site-packages/pandas/io/common.py", line 873, in get_handle
    handle = open(
             ^^^^^
FileNotFoundError: [Errno 2] No such file or directory: '/Users/rwatkins_1/Python projects/preprints_recommender/src/src/discipline_dissimilarity_matrix.csv'
2024-06-26 21:42:29,125 - ERROR - Error occurred: [Errno 2] No such file or directory: '/Users/rwatkins_1/Python projects/preprints_recommender/srcarxiv_taxonomy.csv'
Traceback (most recent call last):
  File "/Users/rwatkins_1/Python projects/preprints_recommender/src/update_user_recs_urssi.py", line 635, in <module>
    update_recommendations()
  File "/Users/rwatkins_1/Python projects/preprints_recommender/src/update_user_recs_urssi.py", line 591, in update_recommendations
    get_arxiv_rec(research_interests)
  File "/Users/rwatkins_1/Python projects/preprints_recommender/src/update_user_recs_urssi.py", line 244, in get_arxiv_rec
    retrieve_articles()
  File "/Users/rwatkins_1/Python projects/preprints_recommender/src/update_user_recs_urssi.py", line 235, in retrieve_articles
    get_arxiv()
  File "/Users/rwatkins_1/Python projects/preprints_recommender/src/update_user_recs_urssi.py", line 183, in get_arxiv
    arxiv_tax_df = pd.read_csv(taxonomy)
                 ^^^^^^^^^^^^^^^^^^^^^
  File "/Users/rwatkins_1/anaconda3/envs/preprint_recs_venv/lib/python3.11/site-packages/pandas/io/parsers/readers.py", line 1026, in read_csv
    return _read(filepath_or_buffer, kwds)
           ^^^^^^^^^^^^^^^^^^^^^^^^^^^^^^^
  File "/Users/rwatkins_1/anaconda3/envs/preprint_recs_venv/lib/python3.11/site-packages/pandas/io/parsers/readers.py", line 620, in _read
    parser = TextFileReader(filepath_or_buffer, **kwds)
             ^^^^^^^^^^^^^^^^^^^^^^^^^^^^^^^^^^^^^^^^^^
  File "/Users/rwatkins_1/anaconda3/envs/preprint_recs_venv/lib/python3.11/site-packages/pandas/io/parsers/readers.py", line 1620, in __init__
    self._engine = self._make_engine(f, self.engine)
                   ^^^^^^^^^^^^^^^^^^^^^^^^^^^^^^^^^
  File "/Users/rwatkins_1/anaconda3/envs/preprint_recs_venv/lib/python3.11/site-packages/pandas/io/parsers/readers.py", line 1880, in _make_engine
    self.handles = get_handle(
                   ^^^^^^^^^^^
  File "/Users/rwatkins_1/anaconda3/envs/preprint_recs_venv/lib/python3.11/site-packages/pandas/io/common.py", line 873, in get_handle
    handle = open(
             ^^^^^
FileNotFoundError: [Errno 2] No such file or directory: '/Users/rwatkins_1/Python projects/preprints_recommender/srcarxiv_taxonomy.csv'
2024-06-26 21:43:33,920 - ERROR - Error occurred: [Errno 2] No such file or directory: '/Users/rwatkins_1/Python projects/preprints_recommender/srcarxiv_taxonomy.csv'
Traceback (most recent call last):
  File "/Users/rwatkins_1/Python projects/preprints_recommender/src/update_user_recs_urssi.py", line 636, in <module>
    update_recommendations()
  File "/Users/rwatkins_1/Python projects/preprints_recommender/src/update_user_recs_urssi.py", line 592, in update_recommendations
    get_arxiv_rec(research_interests)
  File "/Users/rwatkins_1/Python projects/preprints_recommender/src/update_user_recs_urssi.py", line 245, in get_arxiv_rec
    retrieve_articles()
  File "/Users/rwatkins_1/Python projects/preprints_recommender/src/update_user_recs_urssi.py", line 236, in retrieve_articles
    get_arxiv()
  File "/Users/rwatkins_1/Python projects/preprints_recommender/src/update_user_recs_urssi.py", line 184, in get_arxiv
    arxiv_tax_df = pd.read_csv(taxonomy)
                 ^^^^^^^^^^^^^^^^^^^^^
  File "/Users/rwatkins_1/anaconda3/envs/preprint_recs_venv/lib/python3.11/site-packages/pandas/io/parsers/readers.py", line 1026, in read_csv
    return _read(filepath_or_buffer, kwds)
           ^^^^^^^^^^^^^^^^^^^^^^^^^^^^^^^
  File "/Users/rwatkins_1/anaconda3/envs/preprint_recs_venv/lib/python3.11/site-packages/pandas/io/parsers/readers.py", line 620, in _read
    parser = TextFileReader(filepath_or_buffer, **kwds)
             ^^^^^^^^^^^^^^^^^^^^^^^^^^^^^^^^^^^^^^^^^^
  File "/Users/rwatkins_1/anaconda3/envs/preprint_recs_venv/lib/python3.11/site-packages/pandas/io/parsers/readers.py", line 1620, in __init__
    self._engine = self._make_engine(f, self.engine)
                   ^^^^^^^^^^^^^^^^^^^^^^^^^^^^^^^^^
  File "/Users/rwatkins_1/anaconda3/envs/preprint_recs_venv/lib/python3.11/site-packages/pandas/io/parsers/readers.py", line 1880, in _make_engine
    self.handles = get_handle(
                   ^^^^^^^^^^^
  File "/Users/rwatkins_1/anaconda3/envs/preprint_recs_venv/lib/python3.11/site-packages/pandas/io/common.py", line 873, in get_handle
    handle = open(
             ^^^^^
FileNotFoundError: [Errno 2] No such file or directory: '/Users/rwatkins_1/Python projects/preprints_recommender/srcarxiv_taxonomy.csv'
2024-06-26 21:45:03,622 - ERROR - Error occurred: [Errno 2] No such file or directory: '/Users/rwatkins_1/Python projects/preprints_recommender/srcarxiv_taxonomy.csv'
Traceback (most recent call last):
  File "/Users/rwatkins_1/Python projects/preprints_recommender/src/update_user_recs_urssi.py", line 636, in <module>
    update_recommendations()
  File "/Users/rwatkins_1/Python projects/preprints_recommender/src/update_user_recs_urssi.py", line 592, in update_recommendations
    get_arxiv_rec(research_interests)
  File "/Users/rwatkins_1/Python projects/preprints_recommender/src/update_user_recs_urssi.py", line 245, in get_arxiv_rec
    retrieve_articles()
  File "/Users/rwatkins_1/Python projects/preprints_recommender/src/update_user_recs_urssi.py", line 236, in retrieve_articles
    get_arxiv()
  File "/Users/rwatkins_1/Python projects/preprints_recommender/src/update_user_recs_urssi.py", line 184, in get_arxiv
    arxiv_tax_df = pd.read_csv(taxonomy)
                 ^^^^^^^^^^^^^^^^^^^^^
  File "/Users/rwatkins_1/anaconda3/envs/preprint_recs_venv/lib/python3.11/site-packages/pandas/io/parsers/readers.py", line 1026, in read_csv
    return _read(filepath_or_buffer, kwds)
           ^^^^^^^^^^^^^^^^^^^^^^^^^^^^^^^
  File "/Users/rwatkins_1/anaconda3/envs/preprint_recs_venv/lib/python3.11/site-packages/pandas/io/parsers/readers.py", line 620, in _read
    parser = TextFileReader(filepath_or_buffer, **kwds)
             ^^^^^^^^^^^^^^^^^^^^^^^^^^^^^^^^^^^^^^^^^^
  File "/Users/rwatkins_1/anaconda3/envs/preprint_recs_venv/lib/python3.11/site-packages/pandas/io/parsers/readers.py", line 1620, in __init__
    self._engine = self._make_engine(f, self.engine)
                   ^^^^^^^^^^^^^^^^^^^^^^^^^^^^^^^^^
  File "/Users/rwatkins_1/anaconda3/envs/preprint_recs_venv/lib/python3.11/site-packages/pandas/io/parsers/readers.py", line 1880, in _make_engine
    self.handles = get_handle(
                   ^^^^^^^^^^^
  File "/Users/rwatkins_1/anaconda3/envs/preprint_recs_venv/lib/python3.11/site-packages/pandas/io/common.py", line 873, in get_handle
    handle = open(
             ^^^^^
FileNotFoundError: [Errno 2] No such file or directory: '/Users/rwatkins_1/Python projects/preprints_recommender/srcarxiv_taxonomy.csv'
2024-06-26 21:46:18,156 - ERROR - Error occurred: [Errno 2] No such file or directory: '/Users/rwatkins_1/Python projects/preprints_recommender/srcarxiv_taxonomy.csv'
Traceback (most recent call last):
  File "/Users/rwatkins_1/Python projects/preprints_recommender/src/update_user_recs_urssi.py", line 636, in <module>
    update_recommendations()
  File "/Users/rwatkins_1/Python projects/preprints_recommender/src/update_user_recs_urssi.py", line 592, in update_recommendations
    get_arxiv_rec(research_interests)
  File "/Users/rwatkins_1/Python projects/preprints_recommender/src/update_user_recs_urssi.py", line 245, in get_arxiv_rec
    retrieve_articles()
  File "/Users/rwatkins_1/Python projects/preprints_recommender/src/update_user_recs_urssi.py", line 236, in retrieve_articles
    get_arxiv()
  File "/Users/rwatkins_1/Python projects/preprints_recommender/src/update_user_recs_urssi.py", line 183, in get_arxiv
    arxiv_tax_df = pd.read_csv(taxonomy)
                 ^^^^^^^^^^^^^^^^^^^^^
  File "/Users/rwatkins_1/anaconda3/envs/preprint_recs_venv/lib/python3.11/site-packages/pandas/io/parsers/readers.py", line 1026, in read_csv
    return _read(filepath_or_buffer, kwds)
           ^^^^^^^^^^^^^^^^^^^^^^^^^^^^^^^
  File "/Users/rwatkins_1/anaconda3/envs/preprint_recs_venv/lib/python3.11/site-packages/pandas/io/parsers/readers.py", line 620, in _read
    parser = TextFileReader(filepath_or_buffer, **kwds)
             ^^^^^^^^^^^^^^^^^^^^^^^^^^^^^^^^^^^^^^^^^^
  File "/Users/rwatkins_1/anaconda3/envs/preprint_recs_venv/lib/python3.11/site-packages/pandas/io/parsers/readers.py", line 1620, in __init__
    self._engine = self._make_engine(f, self.engine)
                   ^^^^^^^^^^^^^^^^^^^^^^^^^^^^^^^^^
  File "/Users/rwatkins_1/anaconda3/envs/preprint_recs_venv/lib/python3.11/site-packages/pandas/io/parsers/readers.py", line 1880, in _make_engine
    self.handles = get_handle(
                   ^^^^^^^^^^^
  File "/Users/rwatkins_1/anaconda3/envs/preprint_recs_venv/lib/python3.11/site-packages/pandas/io/common.py", line 873, in get_handle
    handle = open(
             ^^^^^
FileNotFoundError: [Errno 2] No such file or directory: '/Users/rwatkins_1/Python projects/preprints_recommender/srcarxiv_taxonomy.csv'
2024-06-26 21:46:51,984 - ERROR - Error occurred: [Errno 2] No such file or directory: '/Users/rwatkins_1/Python projects/preprints_recommender/srcarxiv_taxonomy.csv'
Traceback (most recent call last):
  File "/Users/rwatkins_1/Python projects/preprints_recommender/src/update_user_recs_urssi.py", line 635, in <module>
    update_recommendations()
  File "/Users/rwatkins_1/Python projects/preprints_recommender/src/update_user_recs_urssi.py", line 591, in update_recommendations
    get_arxiv_rec(research_interests)
  File "/Users/rwatkins_1/Python projects/preprints_recommender/src/update_user_recs_urssi.py", line 244, in get_arxiv_rec
    retrieve_articles()
  File "/Users/rwatkins_1/Python projects/preprints_recommender/src/update_user_recs_urssi.py", line 235, in retrieve_articles
    get_arxiv()
  File "/Users/rwatkins_1/Python projects/preprints_recommender/src/update_user_recs_urssi.py", line 183, in get_arxiv
    arxiv_tax_df = pd.read_csv(taxonomy)
                 ^^^^^^^^^^^^^^^^^^^^^
  File "/Users/rwatkins_1/anaconda3/envs/preprint_recs_venv/lib/python3.11/site-packages/pandas/io/parsers/readers.py", line 1026, in read_csv
    return _read(filepath_or_buffer, kwds)
           ^^^^^^^^^^^^^^^^^^^^^^^^^^^^^^^
  File "/Users/rwatkins_1/anaconda3/envs/preprint_recs_venv/lib/python3.11/site-packages/pandas/io/parsers/readers.py", line 620, in _read
    parser = TextFileReader(filepath_or_buffer, **kwds)
             ^^^^^^^^^^^^^^^^^^^^^^^^^^^^^^^^^^^^^^^^^^
  File "/Users/rwatkins_1/anaconda3/envs/preprint_recs_venv/lib/python3.11/site-packages/pandas/io/parsers/readers.py", line 1620, in __init__
    self._engine = self._make_engine(f, self.engine)
                   ^^^^^^^^^^^^^^^^^^^^^^^^^^^^^^^^^
  File "/Users/rwatkins_1/anaconda3/envs/preprint_recs_venv/lib/python3.11/site-packages/pandas/io/parsers/readers.py", line 1880, in _make_engine
    self.handles = get_handle(
                   ^^^^^^^^^^^
  File "/Users/rwatkins_1/anaconda3/envs/preprint_recs_venv/lib/python3.11/site-packages/pandas/io/common.py", line 873, in get_handle
    handle = open(
             ^^^^^
FileNotFoundError: [Errno 2] No such file or directory: '/Users/rwatkins_1/Python projects/preprints_recommender/srcarxiv_taxonomy.csv'
2024-06-26 21:47:15,541 - ERROR - Error occurred: [Errno 2] No such file or directory: '/Users/rwatkins_1/Python projects/preprints_recommender/srcarxiv_taxonomy.csv'
Traceback (most recent call last):
  File "/Users/rwatkins_1/Python projects/preprints_recommender/src/update_user_recs_urssi.py", line 636, in <module>
    update_recommendations()
  File "/Users/rwatkins_1/Python projects/preprints_recommender/src/update_user_recs_urssi.py", line 592, in update_recommendations
    get_arxiv_rec(research_interests)
  File "/Users/rwatkins_1/Python projects/preprints_recommender/src/update_user_recs_urssi.py", line 245, in get_arxiv_rec
    retrieve_articles()
  File "/Users/rwatkins_1/Python projects/preprints_recommender/src/update_user_recs_urssi.py", line 236, in retrieve_articles
    get_arxiv()
  File "/Users/rwatkins_1/Python projects/preprints_recommender/src/update_user_recs_urssi.py", line 183, in get_arxiv
    arxiv_tax_df = pd.read_csv(taxonomy)
                 ^^^^^^^^^^^^^^^^^^^^^
  File "/Users/rwatkins_1/anaconda3/envs/preprint_recs_venv/lib/python3.11/site-packages/pandas/io/parsers/readers.py", line 1026, in read_csv
    return _read(filepath_or_buffer, kwds)
           ^^^^^^^^^^^^^^^^^^^^^^^^^^^^^^^
  File "/Users/rwatkins_1/anaconda3/envs/preprint_recs_venv/lib/python3.11/site-packages/pandas/io/parsers/readers.py", line 620, in _read
    parser = TextFileReader(filepath_or_buffer, **kwds)
             ^^^^^^^^^^^^^^^^^^^^^^^^^^^^^^^^^^^^^^^^^^
  File "/Users/rwatkins_1/anaconda3/envs/preprint_recs_venv/lib/python3.11/site-packages/pandas/io/parsers/readers.py", line 1620, in __init__
    self._engine = self._make_engine(f, self.engine)
                   ^^^^^^^^^^^^^^^^^^^^^^^^^^^^^^^^^
  File "/Users/rwatkins_1/anaconda3/envs/preprint_recs_venv/lib/python3.11/site-packages/pandas/io/parsers/readers.py", line 1880, in _make_engine
    self.handles = get_handle(
                   ^^^^^^^^^^^
  File "/Users/rwatkins_1/anaconda3/envs/preprint_recs_venv/lib/python3.11/site-packages/pandas/io/common.py", line 873, in get_handle
    handle = open(
             ^^^^^
FileNotFoundError: [Errno 2] No such file or directory: '/Users/rwatkins_1/Python projects/preprints_recommender/srcarxiv_taxonomy.csv'
2024-06-26 21:47:39,617 - ERROR - Error occurred: [Errno 2] No such file or directory: '/Users/rwatkins_1/Python projects/preprints_recommender/srcarxiv_taxonomy.csv'
Traceback (most recent call last):
  File "/Users/rwatkins_1/Python projects/preprints_recommender/src/update_user_recs_urssi.py", line 637, in <module>
    update_recommendations()
  File "/Users/rwatkins_1/Python projects/preprints_recommender/src/update_user_recs_urssi.py", line 593, in update_recommendations
    get_arxiv_rec(research_interests)
  File "/Users/rwatkins_1/Python projects/preprints_recommender/src/update_user_recs_urssi.py", line 246, in get_arxiv_rec
    retrieve_articles()
  File "/Users/rwatkins_1/Python projects/preprints_recommender/src/update_user_recs_urssi.py", line 237, in retrieve_articles
    get_arxiv()
  File "/Users/rwatkins_1/Python projects/preprints_recommender/src/update_user_recs_urssi.py", line 183, in get_arxiv
    arxiv_tax_df = pd.read_csv(taxonomy)
                 ^^^^^^^^^^^^^^^^^^^^^
  File "/Users/rwatkins_1/anaconda3/envs/preprint_recs_venv/lib/python3.11/site-packages/pandas/io/parsers/readers.py", line 1026, in read_csv
    return _read(filepath_or_buffer, kwds)
           ^^^^^^^^^^^^^^^^^^^^^^^^^^^^^^^
  File "/Users/rwatkins_1/anaconda3/envs/preprint_recs_venv/lib/python3.11/site-packages/pandas/io/parsers/readers.py", line 620, in _read
    parser = TextFileReader(filepath_or_buffer, **kwds)
             ^^^^^^^^^^^^^^^^^^^^^^^^^^^^^^^^^^^^^^^^^^
  File "/Users/rwatkins_1/anaconda3/envs/preprint_recs_venv/lib/python3.11/site-packages/pandas/io/parsers/readers.py", line 1620, in __init__
    self._engine = self._make_engine(f, self.engine)
                   ^^^^^^^^^^^^^^^^^^^^^^^^^^^^^^^^^
  File "/Users/rwatkins_1/anaconda3/envs/preprint_recs_venv/lib/python3.11/site-packages/pandas/io/parsers/readers.py", line 1880, in _make_engine
    self.handles = get_handle(
                   ^^^^^^^^^^^
  File "/Users/rwatkins_1/anaconda3/envs/preprint_recs_venv/lib/python3.11/site-packages/pandas/io/common.py", line 873, in get_handle
    handle = open(
             ^^^^^
FileNotFoundError: [Errno 2] No such file or directory: '/Users/rwatkins_1/Python projects/preprints_recommender/srcarxiv_taxonomy.csv'
2024-06-26 21:50:28,591 - ERROR - Error occurred: [Errno 2] No such file or directory: '/Users/rwatkins_1/Python projects/preprints_recommender/srcarxiv_taxonomy.csv'
Traceback (most recent call last):
  File "/Users/rwatkins_1/Python projects/preprints_recommender/src/update_user_recs_urssi.py", line 637, in <module>
    update_recommendations()
  File "/Users/rwatkins_1/Python projects/preprints_recommender/src/update_user_recs_urssi.py", line 593, in update_recommendations
    get_arxiv_rec(research_interests)
  File "/Users/rwatkins_1/Python projects/preprints_recommender/src/update_user_recs_urssi.py", line 246, in get_arxiv_rec
    retrieve_articles()
  File "/Users/rwatkins_1/Python projects/preprints_recommender/src/update_user_recs_urssi.py", line 237, in retrieve_articles
    get_arxiv()
  File "/Users/rwatkins_1/Python projects/preprints_recommender/src/update_user_recs_urssi.py", line 184, in get_arxiv
    arxiv_tax_df = pd.read_csv(taxonomy)
                 ^^^^^^^^^^^^^^^^^^^^^
  File "/Users/rwatkins_1/anaconda3/envs/preprint_recs_venv/lib/python3.11/site-packages/pandas/io/parsers/readers.py", line 1026, in read_csv
    return _read(filepath_or_buffer, kwds)
           ^^^^^^^^^^^^^^^^^^^^^^^^^^^^^^^
  File "/Users/rwatkins_1/anaconda3/envs/preprint_recs_venv/lib/python3.11/site-packages/pandas/io/parsers/readers.py", line 620, in _read
    parser = TextFileReader(filepath_or_buffer, **kwds)
             ^^^^^^^^^^^^^^^^^^^^^^^^^^^^^^^^^^^^^^^^^^
  File "/Users/rwatkins_1/anaconda3/envs/preprint_recs_venv/lib/python3.11/site-packages/pandas/io/parsers/readers.py", line 1620, in __init__
    self._engine = self._make_engine(f, self.engine)
                   ^^^^^^^^^^^^^^^^^^^^^^^^^^^^^^^^^
  File "/Users/rwatkins_1/anaconda3/envs/preprint_recs_venv/lib/python3.11/site-packages/pandas/io/parsers/readers.py", line 1880, in _make_engine
    self.handles = get_handle(
                   ^^^^^^^^^^^
  File "/Users/rwatkins_1/anaconda3/envs/preprint_recs_venv/lib/python3.11/site-packages/pandas/io/common.py", line 873, in get_handle
    handle = open(
             ^^^^^
FileNotFoundError: [Errno 2] No such file or directory: '/Users/rwatkins_1/Python projects/preprints_recommender/srcarxiv_taxonomy.csv'
2024-06-26 21:52:42,736 - ERROR - Error occurred: [Errno 2] No such file or directory: '/Users/rwatkins_1/Python projects/preprints_recommender/srcarxiv_taxonomy.csv'
Traceback (most recent call last):
  File "/Users/rwatkins_1/Python projects/preprints_recommender/src/update_user_recs_urssi.py", line 637, in <module>
    update_recommendations()
  File "/Users/rwatkins_1/Python projects/preprints_recommender/src/update_user_recs_urssi.py", line 593, in update_recommendations
    get_arxiv_rec(research_interests)
  File "/Users/rwatkins_1/Python projects/preprints_recommender/src/update_user_recs_urssi.py", line 246, in get_arxiv_rec
    retrieve_articles()
  File "/Users/rwatkins_1/Python projects/preprints_recommender/src/update_user_recs_urssi.py", line 237, in retrieve_articles
    get_arxiv()
  File "/Users/rwatkins_1/Python projects/preprints_recommender/src/update_user_recs_urssi.py", line 184, in get_arxiv
    arxiv_tax_df = pd.read_csv(taxonomy)
                 ^^^^^^^^^^^^^^^^^^^^^
  File "/Users/rwatkins_1/anaconda3/envs/preprint_recs_venv/lib/python3.11/site-packages/pandas/io/parsers/readers.py", line 1026, in read_csv
    return _read(filepath_or_buffer, kwds)
           ^^^^^^^^^^^^^^^^^^^^^^^^^^^^^^^
  File "/Users/rwatkins_1/anaconda3/envs/preprint_recs_venv/lib/python3.11/site-packages/pandas/io/parsers/readers.py", line 620, in _read
    parser = TextFileReader(filepath_or_buffer, **kwds)
             ^^^^^^^^^^^^^^^^^^^^^^^^^^^^^^^^^^^^^^^^^^
  File "/Users/rwatkins_1/anaconda3/envs/preprint_recs_venv/lib/python3.11/site-packages/pandas/io/parsers/readers.py", line 1620, in __init__
    self._engine = self._make_engine(f, self.engine)
                   ^^^^^^^^^^^^^^^^^^^^^^^^^^^^^^^^^
  File "/Users/rwatkins_1/anaconda3/envs/preprint_recs_venv/lib/python3.11/site-packages/pandas/io/parsers/readers.py", line 1880, in _make_engine
    self.handles = get_handle(
                   ^^^^^^^^^^^
  File "/Users/rwatkins_1/anaconda3/envs/preprint_recs_venv/lib/python3.11/site-packages/pandas/io/common.py", line 873, in get_handle
    handle = open(
             ^^^^^
FileNotFoundError: [Errno 2] No such file or directory: '/Users/rwatkins_1/Python projects/preprints_recommender/srcarxiv_taxonomy.csv'
2024-06-26 21:53:44,776 - ERROR - Error occurred: [Errno 2] No such file or directory: '/var/www/html/beta.weshareresearch.com/public_html/beta_recommend/discipline_dissimilarity_matrix.csv'
Traceback (most recent call last):
  File "/Users/rwatkins_1/Python projects/preprints_recommender/src/update_user_recs_urssi.py", line 638, in <module>
    update_recommendations()
  File "/Users/rwatkins_1/Python projects/preprints_recommender/src/update_user_recs_urssi.py", line 598, in update_recommendations
    arxiv_llm_recs = llm_ranked_article(
                     ^^^^^^^^^^^^^^^^^^^
  File "/Users/rwatkins_1/Python projects/preprints_recommender/src/update_user_recs_urssi.py", line 425, in llm_ranked_article
    dissim_df = pd.read_csv(
                ^^^^^^^^^^^^
  File "/Users/rwatkins_1/anaconda3/envs/preprint_recs_venv/lib/python3.11/site-packages/pandas/io/parsers/readers.py", line 1026, in read_csv
    return _read(filepath_or_buffer, kwds)
           ^^^^^^^^^^^^^^^^^^^^^^^^^^^^^^^
  File "/Users/rwatkins_1/anaconda3/envs/preprint_recs_venv/lib/python3.11/site-packages/pandas/io/parsers/readers.py", line 620, in _read
    parser = TextFileReader(filepath_or_buffer, **kwds)
             ^^^^^^^^^^^^^^^^^^^^^^^^^^^^^^^^^^^^^^^^^^
  File "/Users/rwatkins_1/anaconda3/envs/preprint_recs_venv/lib/python3.11/site-packages/pandas/io/parsers/readers.py", line 1620, in __init__
    self._engine = self._make_engine(f, self.engine)
                   ^^^^^^^^^^^^^^^^^^^^^^^^^^^^^^^^^
  File "/Users/rwatkins_1/anaconda3/envs/preprint_recs_venv/lib/python3.11/site-packages/pandas/io/parsers/readers.py", line 1880, in _make_engine
    self.handles = get_handle(
                   ^^^^^^^^^^^
  File "/Users/rwatkins_1/anaconda3/envs/preprint_recs_venv/lib/python3.11/site-packages/pandas/io/common.py", line 873, in get_handle
    handle = open(
             ^^^^^
FileNotFoundError: [Errno 2] No such file or directory: '/var/www/html/beta.weshareresearch.com/public_html/beta_recommend/discipline_dissimilarity_matrix.csv'
2024-06-26 21:55:45,979 - ERROR - Error occurred: [Errno 2] No such file or directory: '/var/www/html/beta.weshareresearch.com/public_html/beta_recommend/discipline_dissimilarity_matrix.csv'
Traceback (most recent call last):
  File "/Users/rwatkins_1/Python projects/preprints_recommender/src/update_user_recs_urssi.py", line 639, in <module>
    update_recommendations()
  File "/Users/rwatkins_1/Python projects/preprints_recommender/src/update_user_recs_urssi.py", line 599, in update_recommendations
    arxiv_llm_recs = llm_ranked_article(
                     ^^^^^^^^^^^^^^^^^^^
  File "/Users/rwatkins_1/Python projects/preprints_recommender/src/update_user_recs_urssi.py", line 426, in llm_ranked_article
    dissim_df = pd.read_csv(
                ^^^^^^^^^^^^
  File "/Users/rwatkins_1/anaconda3/envs/preprint_recs_venv/lib/python3.11/site-packages/pandas/io/parsers/readers.py", line 1026, in read_csv
    return _read(filepath_or_buffer, kwds)
           ^^^^^^^^^^^^^^^^^^^^^^^^^^^^^^^
  File "/Users/rwatkins_1/anaconda3/envs/preprint_recs_venv/lib/python3.11/site-packages/pandas/io/parsers/readers.py", line 620, in _read
    parser = TextFileReader(filepath_or_buffer, **kwds)
             ^^^^^^^^^^^^^^^^^^^^^^^^^^^^^^^^^^^^^^^^^^
  File "/Users/rwatkins_1/anaconda3/envs/preprint_recs_venv/lib/python3.11/site-packages/pandas/io/parsers/readers.py", line 1620, in __init__
    self._engine = self._make_engine(f, self.engine)
                   ^^^^^^^^^^^^^^^^^^^^^^^^^^^^^^^^^
  File "/Users/rwatkins_1/anaconda3/envs/preprint_recs_venv/lib/python3.11/site-packages/pandas/io/parsers/readers.py", line 1880, in _make_engine
    self.handles = get_handle(
                   ^^^^^^^^^^^
  File "/Users/rwatkins_1/anaconda3/envs/preprint_recs_venv/lib/python3.11/site-packages/pandas/io/common.py", line 873, in get_handle
    handle = open(
             ^^^^^
FileNotFoundError: [Errno 2] No such file or directory: '/var/www/html/beta.weshareresearch.com/public_html/beta_recommend/discipline_dissimilarity_matrix.csv'
2024-06-27 14:38:10,913 - ERROR - Error occurred: module 'user_profile' has no attribute 'biography'
Traceback (most recent call last):
  File "/Users/rwatkins_1/Python projects/PreprintScout/src/preprint_scout/recommender_main.py", line 635, in <module>
    update_recommendations()
  File "/Users/rwatkins_1/Python projects/PreprintScout/src/preprint_scout/recommender_main.py", line 592, in update_recommendations
    research_interests()
  File "/Users/rwatkins_1/Python projects/PreprintScout/src/preprint_scout/recommender_main.py", line 576, in research_interests
    research_interests_keywords = get_keywords_llm(user_profile.biography)
                                                   ^^^^^^^^^^^^^^^^^^^^^^
AttributeError: module 'user_profile' has no attribute 'biography'
2024-06-27 15:07:48,418 - ERROR - Error occurred: [Errno 2] No such file or directory: '/outputs/recommendations_2024-06-27 15:04:47.json'
Traceback (most recent call last):
  File "/Users/rwatkins_1/Python projects/PreprintScout/src/preprint_scout/recommender_main.py", line 639, in <module>
    update_recommendations()
  File "/Users/rwatkins_1/Python projects/PreprintScout/src/preprint_scout/recommender_main.py", line 631, in update_recommendations
    save_recommendations_to_json(recommendations)
  File "/Users/rwatkins_1/Python projects/PreprintScout/src/preprint_scout/recommender_main.py", line 573, in save_recommendations_to_json
    with open(file_path, "w") as json_file:
         ^^^^^^^^^^^^^^^^^^^^
FileNotFoundError: [Errno 2] No such file or directory: '/outputs/recommendations_2024-06-27 15:04:47.json'
